Workbook

Sheet Daten
A1: timestamp_iso | B1: participant_id | C1: runde | D1: algo_offer | E1: proband_counter | F1: accepted | G1: finished
A2: 2025-11-01T12:05:47Z | B2: 93fbbf02-d997-4c90-9103-557c7ffc1d69 | C2: 1 | D2: 5500 | E2: 4000 | F2: FALSE | G2: FALSE
A3: 2025-11-01T12:05:56Z | B3: 93fbbf02-d997-4c90-9103-557c7ffc1d69 | C3: 2 | D3: 5454.9 | E3: 2750 | F3: FALSE | G3: FALSE
A4: 2025-11-01T12:06:05Z | B4: 93fbbf02-d997-4c90-9103-557c7ffc1d69 | C4: 3 | D4: 5370.75 | E4: 650 | F4: FALSE | G4: FALSE
A5: 2025-11-01T12:06:11Z | B5: 93fbbf02-d997-4c90-9103-557c7ffc1d69 | C5: 4 | D5: 5202.57 | E5: 4000 | F5: FALSE | G5: FALSE
A6: 2025-11-01T12:06:19Z | B6: 93fbbf02-d997-4c90-9103-557c7ffc1d69 | C6: 5 | D6: 5145.11 | E6: 4950 | F6: TRUE | G6: TRUE
A7: 2025-11-01T12:08:31Z | B7: ab9c5471-9710-4206-8f0b-45df525003f0 | C7: 1 | D7: 5500 | E7: 3000 | F7: FALSE | G7: FALSE
A8: 2025-11-01T12:08:36Z | B8: ab9c5471-9710-4206-8f0b-45df525003f0 | C8: 2 | D8: 5424.83 | E8: 2400 | F8: FALSE | G8: FALSE
A9: 2025-11-01T12:08:42Z | B9: ab9c5471-9710-4206-8f0b-45df525003f0 | C9: 3 | D9: 5330.72 | E9: 2500 | F9: FALSE | G9: FALSE
A10: 2025-11-01T12:08:52Z | B10: ab9c5471-9710-4206-8f0b-45df525003f0 | C10: 4 | D10: 5229.88 | E10: 1500 | F10: FALSE | G10: FALSE
A11: 2025-11-01T12:09:05Z | B11: ab9c5471-9710-4206-8f0b-45df525003f0 | C11: 5 | D11: 5051.67 | E11: 1400 | F11: FALSE | G11: FALSE
A12: 2025-11-01T12:09:18Z | B12: ab9c5471-9710-4206-8f0b-45df525003f0 | C12: 6 | D12: 4783.63 | E12: 1450 | F12: FALSE | G12: FALSE
A13: 2025-11-01T14:05:25Z | B13: 8eb8f2ba-5e67-49dc-a066-7416a0ffb033 | C13: 1 | D13: 5500 | E13: 3000 | F13: FALSE | G13: FALSE
... A17: 2025-11-01T14:05:47Z | B17: 8eb8f2ba-5e67-49dc-a066-7416a0ffb033 | C17: 5 | D17: 5068.43 | E17: 2600 | F17: FALSE | G17: FALSE
A18: 2025-11-01T14:05:53Z | B18: 8eb8f2ba-5e67-49dc-a066-7416a0ffb033 | C18: 6 | D18: 4887.24 | F18: TRUE | G18: TRUE
A19: 2025-11-01T14:06:05Z | B19: bf0416b6-d84c-4e53-9b9e-c4772ea4cee2 | C19: 1 | D19: 5500 | E19: 2400 | F19: FALSE | G19: FALSE
A20: 2025-11-01T14:06:09Z | B20: bf0416b6-d84c-4e53-9b9e-c4772ea4cee2 | C20: 2 | D20: 5406.78 | E20: 2200 | F20: FALSE | G20: FALSE
A21: 2025-11-01T14:06:13Z | B21: bf0416b6-d84c-4e53-9b9e-c4772ea4cee2 | C21: 3 | D21: 5307.01 | E21: 2100 | F21: FALSE | G21: FALSE
A22: 2025-11-01T14:06:17Z | B22: bf0416b6-d84c-4e53-9b9e-c4772ea4cee2 | C22: 4 | D22: 5192.76 | E22: 3600 | F22: FALSE | G22: FALSE
A23: 2025-11-01T14:06:25Z | B23: bf0416b6-d84c-4e53-9b9e-c4772ea4cee2 | C23: 5 | D23: 5116.66 | E23: 2400 | F23: FALSE | G23: FALSE
A24: 2025-11-01T14:06:31Z | B24: bf0416b6-d84c-4e53-9b9e-c4772ea4cee2 | C24: 6 | D24: 4917.25 | E24: 2100 | F24: FALSE | G24: FALSE
A25: 2025-11-01T14:06:42Z | B25: 8c4fbc4c-6bd5-48bc-a9bf-022212ff069d | C25: 1 | D25: 5500 | E25: 2400 | F25: FALSE | G25: FALSE
A26: 2025-11-01T14:06:47Z | B26: 8c4fbc4c-6bd5-48bc-a9bf-022212ff069d | C26: 2 | D26: 5406.78 | E26: 5000 | F26: TRUE | G26: TRUE
A27: 2025-11-02T14:44:40Z | B27: dfea60c1-976e-429c-9579-7983c8f9cc54 | C27: 1 | D27: 5500 | E27: 2500 | F27: FALSE | G27: FALSE
A28: 2025-11-02T14:45:01Z | B28: dfea60c1-976e-429c-9579-7983c8f9cc54 | C28: 2 | D28: 5409.79 | E28: 2200 | F28: FALSE | G28: FALSE
A29: 2025-11-02T14:45:11Z | B29: dfea60c1-976e-429c-9579-7983c8f9cc54 | C29: 3 | D29: 5309.93 | E29: 1600 | F29: FALSE | G29: FALSE
A30: 2025-11-02T14:45:21Z | B30: dfea60c1-976e-429c-9579-7983c8f9cc54 | C30: 4 | D30: 5177.76 | E30: 4750 | F30: FALSE | G30: FALSE
... A41: 2025-11-02T16:06:56Z | B41: 21ec89cc-f616-4125-b7a4-fd7a6d39457f | C41: 4 | D41: 4850 | E41: 4500 | F41: FALSE | G41: FALSE
A42: 2025-11-02T16:07:02Z | B42: 21ec89cc-f616-4125-b7a4-fd7a6d39457f | C42: 5 | D42: 4730 | F42: TRUE | G42: TRUE
A43: 2025-11-02T16:11:17Z | B43: df24ea6c-13ec-4a91-a25f-f65d8f7ccd95 | C43: 1 | D43: 5500 | E43: 4500 | F43: FALSE | G43: FALSE
A44: 2025-11-02T16:11:41Z | B44: df24ea6c-13ec-4a91-a25f-f65d8f7ccd95 | C44: 2 | D44: 5300 | E44: 4600 | F44: FALSE | G44: FALSE
A45: 2025-11-02T16:11:56Z | B45: df24ea6c-13ec-4a91-a25f-f65d8f7ccd95 | C45: 3 | D45: 5100 | E45: 4800 | F45: TRUE | G45: TRUE
A46: 2025-11-02T21:36:35Z | B46: a8fd6e77-367a-42bb-be87-ff8182d6efed | C46: 1 | D46: 5500 | E46: 4000 | F46: FALSE | G46: FALSE
A47: 2025-11-02T21:36:55Z | B47: a8fd6e77-367a-42bb-be87-ff8182d6efed | C47: 2 | D47: 5300 | E47: 4135 | F47: FALSE | G47: FALSE
A48: 2025-11-02T21:38:49Z | B48: a8fd6e77-367a-42bb-be87-ff8182d6efed | C48: 3 | D48: 5100 | E48: 4200 | F48: FALSE | G48: FALSE
A49: 2025-11-02T21:39:09Z | B49: a8fd6e77-367a-42bb-be87-ff8182d6efed | C49: 4 | D49: 4900 | E49: 4250 | F49: FALSE | G49: FALSE
A50: 2025-11-02T21:39:31Z | B50: a8fd6e77-367a-42bb-be87-ff8182d6efed | C50: 5 | D50: 4780 | E50: 4350 | F50: FALSE | G50: FALSE
A51: 2025-11-02T21:39:46Z | B51: a8fd6e77-367a-42bb-be87-ff8182d6efed | C51: 6 | D51: 4660 | E51: 4400 | F51: FALSE | G51: FALSE
A52: 2025-11-02T21:40:07Z | B52: 4c02bf18-a67c-43fb-b3ab-df120f3d7c4e | C52: 1 | D52: 5500 | E52: 4000 | F52: FALSE | G52: FALSE
A53: 2025-11-02T21:40:24Z | B53: 4c02bf18-a67c-43fb-b3ab-df120f3d7c4e | C53: 2 | D53: 5300 | E53: 4800 | F53: TRUE | G53: TRUE
...

Sheet 2025-11-01
H1: Verhandlung_abgeschlossen
A2: 8eb8f2ba-5e67-49dc-a066-7416a0ffb033 | B2: 3000 | C2: 2000 | D2: 1500 | E2: 2800 | F2: 2600 | H2: {='2025-11-08'!H2=_xlfn.XLOOKUP(1, (Daten!$B:$B=$A2)*(Daten!$F:$F=TRUE), IF(ISBLANK(Daten!$E:$E), Daten!$D:$D, Daten!$E:$E), "")} -> FALSE
A3: bf0416b6-d84c-4e53-9b9e-c4772ea4cee2 | B3: 2400 | C3: 2200 | D3: 2100 | E3: 3600 | F3: 2400 | G3: 2100 | H3: {=_xlfn.XLOOKUP(1, (Daten!$B:$B=$A3)*(Daten!$F:$F=TRUE), IF(ISBLANK(Daten!$E:$E), Daten!$D:$D, Daten!$E:$E), "")}
A4: 8c4fbc4c-6bd5-48bc-a9bf-022212ff069d | B4: 2400 | C4: 5000 | H4: {=_xlfn.XLOOKUP(1, (Daten!$B:$B=$A4)*(Daten!$F:$F=TRUE), IF(ISBLANK(Daten!$E:$E), Daten!$D:$D, Daten!$E:$E), "")} -> 5000

Sheet 2025-11-02
A1: participant_id | B1: r1 | C1: r2 | D1: r3 | E1: r4 | F1: r5 | G1: r6 | H1: Verhandlung-abgeschlossen
A2: dfea60c1-976e-429c-9579-7983c8f9cc54 | B2: 2500 | C2: 2200 | D2: 1600 | E2: 4750 | F2: 4300 | G2: 100 | H2: {=_xlfn.XLOOKUP(1, (Daten!$B:$B=$A2)*(Daten!$F:$F=TRUE), IF(ISBLANK(Daten!$E:$E), Daten!$D:$D, Daten!$E:$E), "")}
A3: 0b903683-c303-4c80-91bd-ace09e301b5d | B3: 100 | C3: 1500 | D3: 1300 | E3: 1250 | F3: 4850 | H3: {=_xlfn.XLOOKUP(1, (Daten!$B:$B=$A3)*(Daten!$F:$F=TRUE), IF(ISBLANK(Daten!$E:$E), Daten!$D:$D, Daten!$E:$E), "")} -> 4850
A4: 21ec89cc-f616-4125-b7a4-fd7a6d39457f | B4: 3800 | C4: 4000 | D4: 4300 | E4: 4500
A5: df24ea6c-13ec-4a91-a25f-f65d8f7ccd95 | B5: 4500 | C5: 4600 | D5: 4800
A6: a8fd6e77-367a-42bb-be87-ff8182d6efed | B6: 4000 | C6: 4135 | D6: 4200 | E6: 4250 | F6: 4350 | G6: 4400
A7: 4c02bf18-a67c-43fb-b3ab-df120f3d7c4e | B7: 4000 | C7: 4800

Sheet 2025-11-03
A1: participant_id | B1: r1 | C1: r2 | D1: r3 | E1: r4 | F1: r5 | G1: r6
A2: 74533d4b-e541-4072-b7bc-733732daff06 | B2: 4000 | H2: {=_xlfn.XLOOKUP(1, (Daten!$B:$B=$A2)*(Daten!$F:$F=TRUE), IF(ISBLANK(Daten!$E:$E), Daten!$D:$D, Daten!$E:$E), "")}
A3: 106e23fb-2c21-41af-9792-2801e59f871e | B3: 4800 | H3: {=_xlfn.XLOOKUP(1, (Daten!$B:$B=$A3)*(Daten!$F:$F=TRUE), IF(ISBLANK(Daten!$E:$E), Daten!$D:$D, Daten!$E:$E), "")} -> 4800
A4: 57fb6c34-e82e-4918-9340-44bc7811c484 | B4: 3800 | C4: 4000 | D4: 4010 | E4: 4700 | F4: 4705 | H4: {=_xlfn.XLOOKUP(1, (Daten!$B:$B=$A4)*(Daten!$F:$F=TRUE), IF(ISBLANK(Daten!$E:$E), Daten!$D:$D, Daten!$E:$E), "")} -> 4705
A5: ef4ad9f3-acd6-4d2a-afbf-cc1235075c39 | B5: 3000 | C5: 3500 | D5: 3600 | E5: 3700 | F5: 3800 | H5: {=_xlfn.XLOOKUP(1, (Daten!$B:$B=$A5)*(Daten!$F:$F=TRUE), IF(ISBLANK(Daten!$E:$E), Daten!$D:$D, Daten!$E:$E), "")} -> 4432.36

Sheet 2025-11-04
A1: participant_id | B1: r1 | C1: r2 | D1: r3 | E1: r4 | F1: r5 | G1: r6
A2: 1cd1281e-93ec-4dde-8e59-670276a506e8 | B2: 1000 | C2: 1500 | D2: 1600 | E2: 1700 | F2: 1800 | G2: 1900 | H2: {=_xlfn.XLOOKUP(1, (Daten!$B:$B=$A2)*(Daten!$F:$F=TRUE), IF(ISBLANK(Daten!$E:$E), Daten!$D:$D, Daten!$E:$E), "")}
A3: 0fdf0148-5a98-40b0-96f0-ebbd6ed48f55 | B3: 1000 | C3: 1100 | D3: 1200 | E3: 1300 | F3: 1400 | G3: 1500 | H3: {=_xlfn.XLOOKUP(1, (Daten!$B:$B=$A3)*(Daten!$F:$F=TRUE), IF(ISBLANK(Daten!$E:$E), Daten!$D:$D, Daten!$E:$E), "")}
A4: 1bca081b-9032-4874-9fa3-10d9878c21e1 | B4: 1000 | C4: 1100 | D4: 1200 | E4: 1300 | F4: 1400 | G4: 1500 | H4: {=_xlfn.XLOOKUP(1, (Daten!$B:$B=$A4)*(Daten!$F:$F=TRUE), IF(ISBLANK(Daten!$E:$E), Daten!$D:$D, Daten!$E:$E), "")}
A5: bbffed68-0cb6-46bc-95b4-05fff777e082 | B5: 1000 | C5: 1100 | D5: 1200 | E5: 1300 | F5: 1400 | G5: 1450 | H5: {=_xlfn.XLOOKUP(1, (Daten!$B:$B=$A5)*(Daten!$F:$F=TRUE), IF(ISBLANK(Daten!$E:$E), Daten!$D:$D, Daten!$E:$E), "")}
A6: 4569a795-d85c-4ddc-a8cf-fd5f5984072d | B6: 1000 | C6: 1100 | D6: 1200 | E6: 1300 | F6: 1400 | G6: 1500 | H6: {=_xlfn.XLOOKUP(1, (Daten!$B:$B=$A6)*(Daten!$F:$F=TRUE), IF(ISBLANK(Daten!$E:$E), Daten!$D:$D, Daten!$E:$E), "")}
A7: 76acf4f9-e4b4-44e8-bf9a-8e65d53562ab | B7: 1100 | C7: 1200 | H7: {=_xlfn.XLOOKUP(1, (Daten!$B:$B=$A7)*(Daten!$F:$F=TRUE), IF(ISBLANK(Daten!$E:$E), Daten!$D:$D, Daten!$E:$E), "")}
A8: 476fdfdd-ff51-4bd2-9333-90178d4b30c9 | B8: 1100 | C8: 1200 | D8: 1300 | H8: {=_xlfn.XLOOKUP(1, (Daten!$B:$B=$A8)*(Daten!$F:$F=TRUE), IF(ISBLANK(Daten!$E:$E), Daten!$D:$D, Daten!$E:$E), "")} -> 4600
A9: 065f7123-88cf-4d7d-80a2-8d6d7ccd1604 | B9: 1100 | H9: {=_xlfn.XLOOKUP(1, (Daten!$B:$B=$A9)*(Daten!$F:$F=TRUE), IF(ISBLANK(Daten!$E:$E), Daten!$D:$D, Daten!$E:$E), "")}
A10: 512cef79-7c37-41fc-809c-e6bcd1831dd3 | B10: 1000 | H10: {=_xlfn.XLOOKUP(1, (Daten!$B:$B=$A10)*(Daten!$F:$F=TRUE), IF(ISBLANK(Daten!$E:$E), Daten!$D:$D, Daten!$E:$E), "")}
A11: 248d6e93-3aa8-46d7-9891-9ce72a70b2b7 | B11: 1000 | H11: {=_xlfn.XLOOKUP(1, (Daten!$B:$B=$A11)*(Daten!$F:$F=TRUE), IF(ISBLANK(Daten!$E:$E), Daten!$D:$D, Daten!$E:$E), "")}
A12: 3ceb1ae6-2981-4f2b-b1a7-0d069b7501ac | B12: 1000 | C12: 1100 | D12: 1200 | E12: 1300 | F12: 1400 | G12: 1500 | H12: {=_xlfn.XLOOKUP(1, (Daten!$B:$B=$A12)*(Daten!$F:$F=TRUE), IF(ISBLANK(Daten!$E:$E), Daten!$D:$D, Daten!$E:$E), "")}

Sheet 2025-11-05
A1: participant_id | B1: r1 | C1: r2 | D1: r3 | E1: r4 | F1: r5 | G1: r6
A2: 04b9211e-6527-477f-b5a5-7054d8a6efdb | B2: 1000 | C2: 1100 | D2: 1200 | E2: 1300 | F2: 1400 | G2: 1500

Sheet 2025-11-08
A1: participant_id | B1: r1 | C1: r2 | D1: r3 | E1: r4 | F1: r5 | G1: r6
A2: ef92c556-ad23-49a2-b3cb-ae82ac5fef79 | B2: 3500 | C2: 3700 | D2: 4100 | E2: 4200 | F2: 4400 | H2: {=_xlfn.XLOOKUP(1, (Daten!$B:$B=$A2)*(Daten!$F:$F=TRUE), IF(ISBLANK(Daten!$E:$E), Daten!$D:$D, Daten!$E:$E), "")} -> 4610
A3: 8861516c-8a86-47d6-af82-a581353c5435 | B3: 1000 | C3: 4000 | D3: 4250 | E3: 4000 | F3: 4500 | G3: 4500 | H3: {=_xlfn.XLOOKUP(1, (Daten!$B:$B=$A3)*(Daten!$F:$F=TRUE), IF(ISBLANK(Daten!$E:$E), Daten!$D:$D, Daten!$E:$E), "")} -> 4440
A4: c55e4011-1f10-474e-bf7f-9077d9310dfa | B4: 1000 | C4: 1010 | D4: 1100 | E4: 1200 | F4: 1300 | G4: 1400 | H4: {=_xlfn.XLOOKUP(1, (Daten!$B:$B=$A4)*(Daten!$F:$F=TRUE), IF(ISBLANK(Daten!$E:$E), Daten!$D:$D, Daten!$E:$E), "")}
